Warning: window 'pinocchio' already created.
The previously created objects will not be destroyed and do not have to be created again.
[-6.  -5.4 -4.8 -4.2 -3.6 -3.  -2.4 -1.8 -1.2 -0.6  0.   0.6  1.2  1.8
  2.4  3.   3.6  4.2  4.8  5.4  6. ]
save_dir:  models/double_pendulum/3000_episodes1000_episode
Episode:  1
Episode : 1 total_reward : -3272.37 Avg Reward : -3272.37
Episode:  2
Episode : 2 total_reward : -3272.37 Avg Reward : -3272.37
Episode:  3
WARNING:tensorflow:No training configuration found in save file, so the model was *not* compiled. Compile it manually.
Episode : 3 total_reward : -3272.37 Avg Reward : -3272.37
Episode:  4
Episode : 4 total_reward : -3272.37 Avg Reward : -3272.37
Episode:  5
Episode : 5 total_reward : -3272.37 Avg Reward : -3272.37
Episode:  6
Episode : 6 total_reward : -3272.37 Avg Reward : -3272.37
Episode:  7
Traceback (most recent call last):
  File "DQN template.py", line 383, in <module>
    test_dqn(env, episodes, save_dir)
  File "DQN template.py", line 321, in test_dqn
    q_values = Q(input)
  File "/home/edo/.local/lib/python3.8/site-packages/keras/utils/traceback_utils.py", line 65, in error_handler
    return fn(*args, **kwargs)
  File "/home/edo/.local/lib/python3.8/site-packages/keras/engine/training.py", line 558, in __call__
    return super().__call__(*args, **kwargs)
  File "/home/edo/.local/lib/python3.8/site-packages/keras/utils/traceback_utils.py", line 65, in error_handler
    return fn(*args, **kwargs)
  File "/home/edo/.local/lib/python3.8/site-packages/keras/engine/base_layer.py", line 1145, in __call__
    outputs = call_fn(inputs, *args, **kwargs)
  File "/home/edo/.local/lib/python3.8/site-packages/keras/utils/traceback_utils.py", line 96, in error_handler
    return fn(*args, **kwargs)
  File "/home/edo/.local/lib/python3.8/site-packages/keras/engine/functional.py", line 512, in call
    return self._run_internal_graph(inputs, training=training, mask=mask)
  File "/home/edo/.local/lib/python3.8/site-packages/keras/engine/functional.py", line 669, in _run_internal_graph
    outputs = node.layer(*args, **kwargs)
  File "/home/edo/.local/lib/python3.8/site-packages/keras/utils/traceback_utils.py", line 65, in error_handler
    return fn(*args, **kwargs)
  File "/home/edo/.local/lib/python3.8/site-packages/keras/engine/base_layer.py", line 1145, in __call__
    outputs = call_fn(inputs, *args, **kwargs)
  File "/home/edo/.local/lib/python3.8/site-packages/keras/utils/traceback_utils.py", line 96, in error_handler
    return fn(*args, **kwargs)
  File "/home/edo/.local/lib/python3.8/site-packages/keras/layers/core/dense.py", line 241, in call
    outputs = tf.matmul(a=inputs, b=self.kernel)
  File "/home/edo/.local/lib/python3.8/site-packages/tensorflow/python/util/traceback_utils.py", line 150, in error_handler
    return fn(*args, **kwargs)
  File "/home/edo/.local/lib/python3.8/site-packages/tensorflow/python/util/dispatch.py", line 1176, in op_dispatch_handler
    return dispatch_target(*args, **kwargs)
  File "/home/edo/.local/lib/python3.8/site-packages/tensorflow/python/ops/math_ops.py", line 3766, in matmul
    return gen_math_ops.mat_mul(
  File "/home/edo/.local/lib/python3.8/site-packages/tensorflow/python/ops/gen_math_ops.py", line 6013, in mat_mul
    _result = pywrap_tfe.TFE_Py_FastPathExecute(
KeyboardInterrupt
Traceback (most recent call last):
  File "DQN template.py", line 383, in <module>
    test_dqn(env, episodes, save_dir)
  File "DQN template.py", line 321, in test_dqn
    q_values = Q(input)
  File "/home/edo/.local/lib/python3.8/site-packages/keras/utils/traceback_utils.py", line 65, in error_handler
    return fn(*args, **kwargs)
  File "/home/edo/.local/lib/python3.8/site-packages/keras/engine/training.py", line 558, in __call__
    return super().__call__(*args, **kwargs)
  File "/home/edo/.local/lib/python3.8/site-packages/keras/utils/traceback_utils.py", line 65, in error_handler
    return fn(*args, **kwargs)
  File "/home/edo/.local/lib/python3.8/site-packages/keras/engine/base_layer.py", line 1145, in __call__
    outputs = call_fn(inputs, *args, **kwargs)
  File "/home/edo/.local/lib/python3.8/site-packages/keras/utils/traceback_utils.py", line 96, in error_handler
    return fn(*args, **kwargs)
  File "/home/edo/.local/lib/python3.8/site-packages/keras/engine/functional.py", line 512, in call
    return self._run_internal_graph(inputs, training=training, mask=mask)
  File "/home/edo/.local/lib/python3.8/site-packages/keras/engine/functional.py", line 669, in _run_internal_graph
    outputs = node.layer(*args, **kwargs)
  File "/home/edo/.local/lib/python3.8/site-packages/keras/utils/traceback_utils.py", line 65, in error_handler
    return fn(*args, **kwargs)
  File "/home/edo/.local/lib/python3.8/site-packages/keras/engine/base_layer.py", line 1145, in __call__
    outputs = call_fn(inputs, *args, **kwargs)
  File "/home/edo/.local/lib/python3.8/site-packages/keras/utils/traceback_utils.py", line 96, in error_handler
    return fn(*args, **kwargs)
  File "/home/edo/.local/lib/python3.8/site-packages/keras/layers/core/dense.py", line 241, in call
    outputs = tf.matmul(a=inputs, b=self.kernel)
  File "/home/edo/.local/lib/python3.8/site-packages/tensorflow/python/util/traceback_utils.py", line 150, in error_handler
    return fn(*args, **kwargs)
  File "/home/edo/.local/lib/python3.8/site-packages/tensorflow/python/util/dispatch.py", line 1176, in op_dispatch_handler
    return dispatch_target(*args, **kwargs)
  File "/home/edo/.local/lib/python3.8/site-packages/tensorflow/python/ops/math_ops.py", line 3766, in matmul
    return gen_math_ops.mat_mul(
  File "/home/edo/.local/lib/python3.8/site-packages/tensorflow/python/ops/gen_math_ops.py", line 6013, in mat_mul
    _result = pywrap_tfe.TFE_Py_FastPathExecute(
KeyboardInterrupt