WARNING:tensorflow:No training configuration found in save file, so the model was *not* compiled. Compile it manually.
Traceback (most recent call last):
  File "DQN template.py", line 406, in <module>
    #test_dqn(env, episodes, save_dir)
  File "DQN template.py", line 347, in test_dqn
    q_values = Q(input)
  File "/home/edo/.local/lib/python3.8/site-packages/keras/utils/traceback_utils.py", line 65, in error_handler
    return fn(*args, **kwargs)
  File "/home/edo/.local/lib/python3.8/site-packages/keras/engine/training.py", line 558, in __call__
    return super().__call__(*args, **kwargs)
Episode:  1
  File "/home/edo/.local/lib/python3.8/site-packages/keras/utils/traceback_utils.py", line 65, in error_handler
    return fn(*args, **kwargs)
  File "/home/edo/.local/lib/python3.8/site-packages/keras/engine/base_layer.py", line 1145, in __call__
    outputs = call_fn(inputs, *args, **kwargs)
  File "/home/edo/.local/lib/python3.8/site-packages/keras/utils/traceback_utils.py", line 96, in error_handler
    return fn(*args, **kwargs)
  File "/home/edo/.local/lib/python3.8/site-packages/keras/engine/functional.py", line 512, in call
    return self._run_internal_graph(inputs, training=training, mask=mask)
  File "/home/edo/.local/lib/python3.8/site-packages/keras/engine/functional.py", line 669, in _run_internal_graph
    outputs = node.layer(*args, **kwargs)
  File "/home/edo/.local/lib/python3.8/site-packages/keras/utils/traceback_utils.py", line 65, in error_handler
    return fn(*args, **kwargs)
  File "/home/edo/.local/lib/python3.8/site-packages/keras/engine/base_layer.py", line 1145, in __call__
    outputs = call_fn(inputs, *args, **kwargs)
  File "/home/edo/.local/lib/python3.8/site-packages/keras/utils/traceback_utils.py", line 96, in error_handler
    return fn(*args, **kwargs)
  File "/home/edo/.local/lib/python3.8/site-packages/keras/layers/core/dense.py", line 252, in call
    outputs = tf.nn.bias_add(outputs, self.bias)
  File "/home/edo/.local/lib/python3.8/site-packages/tensorflow/python/util/traceback_utils.py", line 150, in error_handler
    return fn(*args, **kwargs)
  File "/home/edo/.local/lib/python3.8/site-packages/tensorflow/python/util/dispatch.py", line 1176, in op_dispatch_handler
    return dispatch_target(*args, **kwargs)
  File "/home/edo/.local/lib/python3.8/site-packages/tensorflow/python/ops/nn_ops.py", line 3554, in bias_add
    return gen_nn_ops.bias_add(value, bias, data_format=data_format, name=name)
  File "/home/edo/.local/lib/python3.8/site-packages/tensorflow/python/ops/gen_nn_ops.py", line 849, in bias_add
    _result = pywrap_tfe.TFE_Py_FastPathExecute(
KeyboardInterrupt
Traceback (most recent call last):
  File "DQN template.py", line 406, in <module>
    #test_dqn(env, episodes, save_dir)
  File "DQN template.py", line 347, in test_dqn
    q_values = Q(input)
  File "/home/edo/.local/lib/python3.8/site-packages/keras/utils/traceback_utils.py", line 65, in error_handler
    return fn(*args, **kwargs)
  File "/home/edo/.local/lib/python3.8/site-packages/keras/engine/training.py", line 558, in __call__
    return super().__call__(*args, **kwargs)
  File "/home/edo/.local/lib/python3.8/site-packages/keras/utils/traceback_utils.py", line 65, in error_handler
    return fn(*args, **kwargs)
  File "/home/edo/.local/lib/python3.8/site-packages/keras/engine/base_layer.py", line 1145, in __call__
    outputs = call_fn(inputs, *args, **kwargs)
  File "/home/edo/.local/lib/python3.8/site-packages/keras/utils/traceback_utils.py", line 96, in error_handler
    return fn(*args, **kwargs)
  File "/home/edo/.local/lib/python3.8/site-packages/keras/engine/functional.py", line 512, in call
    return self._run_internal_graph(inputs, training=training, mask=mask)
  File "/home/edo/.local/lib/python3.8/site-packages/keras/engine/functional.py", line 669, in _run_internal_graph
    outputs = node.layer(*args, **kwargs)
  File "/home/edo/.local/lib/python3.8/site-packages/keras/utils/traceback_utils.py", line 65, in error_handler
    return fn(*args, **kwargs)
  File "/home/edo/.local/lib/python3.8/site-packages/keras/engine/base_layer.py", line 1145, in __call__
    outputs = call_fn(inputs, *args, **kwargs)
  File "/home/edo/.local/lib/python3.8/site-packages/keras/utils/traceback_utils.py", line 96, in error_handler
    return fn(*args, **kwargs)
  File "/home/edo/.local/lib/python3.8/site-packages/keras/layers/core/dense.py", line 252, in call
    outputs = tf.nn.bias_add(outputs, self.bias)
  File "/home/edo/.local/lib/python3.8/site-packages/tensorflow/python/util/traceback_utils.py", line 150, in error_handler
    return fn(*args, **kwargs)
  File "/home/edo/.local/lib/python3.8/site-packages/tensorflow/python/util/dispatch.py", line 1176, in op_dispatch_handler
    return dispatch_target(*args, **kwargs)
  File "/home/edo/.local/lib/python3.8/site-packages/tensorflow/python/ops/nn_ops.py", line 3554, in bias_add
    return gen_nn_ops.bias_add(value, bias, data_format=data_format, name=name)
  File "/home/edo/.local/lib/python3.8/site-packages/tensorflow/python/ops/gen_nn_ops.py", line 849, in bias_add
    _result = pywrap_tfe.TFE_Py_FastPathExecute(
KeyboardInterrupt