self.nx:  2
len(x0):  2
[9, 9, 9, 7, 9, 9, 1, 7, 6, 12, 11, 5, 8, 8, 0, 10, 11, 1, 5, 10, 4, 0, 1, 12, 6, 12, 2, 10, 0, 2, 8, 8, 6, 1, 12, 4, 11, 9, 3, 11, 5, 4, 3, 12, 10, 12, 10, 12, 2, 3, 9, 6, 2, 5, 4, 4, 7, 11, 9, 1, 3, 1, 8, 12]
Traceback (most recent call last):
  File "DQN template.py", line 320, in <module>
    train_dqn(dqn, env, episodes, critic_optimizer, save_dir)
  File "DQN template.py", line 210, in train_dqn
    q_pred = Q(np.array(states), training = True)[indices, actions]
  File "/home/edo/.local/lib/python3.8/site-packages/tensorflow/python/util/traceback_utils.py", line 153, in error_handler
    raise e.with_traceback(filtered_tb) from None
  File "/home/edo/.local/lib/python3.8/site-packages/tensorflow/python/framework/ops.py", line 7262, in raise_from_not_ok_status
    raise core._status_to_exception(e) from None  # pylint: disable=protected-access
tensorflow.python.framework.errors_impl.InvalidArgumentError: {{function_node __wrapped__GatherV2_device_/job:localhost/replica:0/task:0/device:CPU:0}} indices[63] = 705 is not in [0, 704) [Op:GatherV2]
Traceback (most recent call last):
  File "DQN template.py", line 320, in <module>
    train_dqn(dqn, env, episodes, critic_optimizer, save_dir)
  File "DQN template.py", line 210, in train_dqn
    q_pred = Q(np.array(states), training = True)[indices, actions]
  File "/home/edo/.local/lib/python3.8/site-packages/tensorflow/python/util/traceback_utils.py", line 153, in error_handler
    raise e.with_traceback(filtered_tb) from None
  File "/home/edo/.local/lib/python3.8/site-packages/tensorflow/python/framework/ops.py", line 7262, in raise_from_not_ok_status
    raise core._status_to_exception(e) from None  # pylint: disable=protected-access
tensorflow.python.framework.errors_impl.InvalidArgumentError: {{function_node __wrapped__GatherV2_device_/job:localhost/replica:0/task:0/device:CPU:0}} indices[63] = 705 is not in [0, 704) [Op:GatherV2]