
WARNING:tensorflow:No training configuration found in save file, so the model was *not* compiled. Compile it manually.
Episode:  1
Episode : 1 total_reward : -40.67 Avg Reward : -40.67
Episode:  2
Episode : 2 total_reward : -122.24 Avg Reward : -81.45
Episode:  3
Episode : 3 total_reward : -275.31 Avg Reward : -146.07
Episode:  4
Episode : 4 total_reward : -120.50 Avg Reward : -139.68
Episode:  5
Episode : 5 total_reward : -121.88 Avg Reward : -136.12
Episode:  6
Episode : 6 total_reward : -111.65 Avg Reward : -132.04
Episode:  7
Episode : 7 total_reward : -110.10 Avg Reward : -128.91
Episode:  8
Episode : 8 total_reward : -321.43 Avg Reward : -152.97
Episode:  9
Episode : 9 total_reward : -112.66 Avg Reward : -148.49
Episode:  10
Episode : 10 total_reward : -212.59 Avg Reward : -154.90
Episode:  11
Traceback (most recent call last):
  File "DQN template.py", line 408, in <module>
    test_dqn(env, episodes, save_dir)
  File "DQN template.py", line 349, in test_dqn
    q_values = Q(input)
  File "/home/edo/.local/lib/python3.8/site-packages/keras/utils/traceback_utils.py", line 65, in error_handler
    return fn(*args, **kwargs)
  File "/home/edo/.local/lib/python3.8/site-packages/keras/engine/training.py", line 558, in __call__
    return super().__call__(*args, **kwargs)
  File "/home/edo/.local/lib/python3.8/site-packages/keras/utils/traceback_utils.py", line 65, in error_handler
    return fn(*args, **kwargs)
  File "/home/edo/.local/lib/python3.8/site-packages/keras/engine/base_layer.py", line 1145, in __call__
    outputs = call_fn(inputs, *args, **kwargs)
  File "/home/edo/.local/lib/python3.8/site-packages/keras/utils/traceback_utils.py", line 96, in error_handler
    return fn(*args, **kwargs)
  File "/home/edo/.local/lib/python3.8/site-packages/keras/engine/functional.py", line 512, in call
    return self._run_internal_graph(inputs, training=training, mask=mask)
  File "/home/edo/.local/lib/python3.8/site-packages/keras/engine/functional.py", line 669, in _run_internal_graph
    outputs = node.layer(*args, **kwargs)
  File "/home/edo/.local/lib/python3.8/site-packages/keras/utils/traceback_utils.py", line 65, in error_handler
    return fn(*args, **kwargs)
  File "/home/edo/.local/lib/python3.8/site-packages/keras/engine/base_layer.py", line 1134, in __call__
    namescope_stack.enter_context(tf.name_scope(name_scope))
  File "/usr/lib/python3.8/contextlib.py", line 425, in enter_context
    result = _cm_type.__enter__(cm)
  File "/home/edo/.local/lib/python3.8/site-packages/tensorflow/python/framework/ops.py", line 7027, in __enter__
    if ctx.executing_eagerly():
  File "/home/edo/.local/lib/python3.8/site-packages/tensorflow/python/eager/context.py", line 978, in executing_eagerly
    return self._thread_local_data.is_eager
KeyboardInterrupt
Traceback (most recent call last):
  File "DQN template.py", line 408, in <module>
    test_dqn(env, episodes, save_dir)
  File "DQN template.py", line 349, in test_dqn
    q_values = Q(input)
  File "/home/edo/.local/lib/python3.8/site-packages/keras/utils/traceback_utils.py", line 65, in error_handler
    return fn(*args, **kwargs)
  File "/home/edo/.local/lib/python3.8/site-packages/keras/engine/training.py", line 558, in __call__
    return super().__call__(*args, **kwargs)
  File "/home/edo/.local/lib/python3.8/site-packages/keras/utils/traceback_utils.py", line 65, in error_handler
    return fn(*args, **kwargs)
  File "/home/edo/.local/lib/python3.8/site-packages/keras/engine/base_layer.py", line 1145, in __call__
    outputs = call_fn(inputs, *args, **kwargs)
  File "/home/edo/.local/lib/python3.8/site-packages/keras/utils/traceback_utils.py", line 96, in error_handler
    return fn(*args, **kwargs)
  File "/home/edo/.local/lib/python3.8/site-packages/keras/engine/functional.py", line 512, in call
    return self._run_internal_graph(inputs, training=training, mask=mask)
  File "/home/edo/.local/lib/python3.8/site-packages/keras/engine/functional.py", line 669, in _run_internal_graph
    outputs = node.layer(*args, **kwargs)
  File "/home/edo/.local/lib/python3.8/site-packages/keras/utils/traceback_utils.py", line 65, in error_handler
    return fn(*args, **kwargs)
  File "/home/edo/.local/lib/python3.8/site-packages/keras/engine/base_layer.py", line 1134, in __call__
    namescope_stack.enter_context(tf.name_scope(name_scope))
  File "/usr/lib/python3.8/contextlib.py", line 425, in enter_context
    result = _cm_type.__enter__(cm)
  File "/home/edo/.local/lib/python3.8/site-packages/tensorflow/python/framework/ops.py", line 7027, in __enter__
    if ctx.executing_eagerly():
  File "/home/edo/.local/lib/python3.8/site-packages/tensorflow/python/eager/context.py", line 978, in executing_eagerly
    return self._thread_local_data.is_eager
KeyboardInterrupt