2023-06-13 08:25:45,965 INFO    StreamThr :743961 [internal.py:wandb_internal():86] W&B internal server running at pid: 743961, started at: 2023-06-13 08:25:45.965340
2023-06-13 08:25:45,967 DEBUG   HandlerThread:743961 [handler.py:handle_request():144] handle_request: status
2023-06-13 08:25:45,972 INFO    WriterThread:743961 [datastore.py:open_for_write():85] open: /home/edo/Desktop/orc/03_assignment/wandb/run-20230613_082545-n970g7bs/run-n970g7bs.wandb
2023-06-13 08:25:45,972 DEBUG   SenderThread:743961 [sender.py:send():375] send: header
2023-06-13 08:25:45,997 DEBUG   SenderThread:743961 [sender.py:send():375] send: run
2023-06-13 08:25:49,657 INFO    SenderThread:743961 [retry.py:__call__():172] Retry attempt failed:
Traceback (most recent call last):
  File "/home/edo/.local/lib/python3.8/site-packages/urllib3/connection.py", line 200, in _new_conn
    sock = connection.create_connection(
  File "/home/edo/.local/lib/python3.8/site-packages/urllib3/util/connection.py", line 60, in create_connection
    for res in socket.getaddrinfo(host, port, family, socket.SOCK_STREAM):
  File "/usr/lib/python3.8/socket.py", line 918, in getaddrinfo
    for res in _socket.getaddrinfo(host, port, family, type, proto, flags):
socket.gaierror: [Errno -3] Temporary failure in name resolution

The above exception was the direct cause of the following exception:

Traceback (most recent call last):
  File "/home/edo/.local/lib/python3.8/site-packages/urllib3/connectionpool.py", line 790, in urlopen
    response = self._make_request(
  File "/home/edo/.local/lib/python3.8/site-packages/urllib3/connectionpool.py", line 491, in _make_request
    raise new_e
  File "/home/edo/.local/lib/python3.8/site-packages/urllib3/connectionpool.py", line 467, in _make_request
    self._validate_conn(conn)
  File "/home/edo/.local/lib/python3.8/site-packages/urllib3/connectionpool.py", line 1092, in _validate_conn
    conn.connect()
  File "/home/edo/.local/lib/python3.8/site-packages/urllib3/connection.py", line 604, in connect
    self.sock = sock = self._new_conn()
  File "/home/edo/.local/lib/python3.8/site-packages/urllib3/connection.py", line 207, in _new_conn
    raise NameResolutionError(self.host, self, e) from e
urllib3.exceptions.NameResolutionError: <urllib3.connection.HTTPSConnection object at 0x7f50f09ca490>: Failed to resolve 'api.wandb.ai' ([Errno -3] Temporary failure in name resolution)

The above exception was the direct cause of the following exception:

Traceback (most recent call last):
  File "/usr/lib/python3/dist-packages/requests/adapters.py", line 439, in send
    resp = conn.urlopen(
  File "/home/edo/.local/lib/python3.8/site-packages/urllib3/connectionpool.py", line 844, in urlopen
    retries = retries.increment(
  File "/home/edo/.local/lib/python3.8/site-packages/urllib3/util/retry.py", line 515, in increment
    raise MaxRetryError(_pool, url, reason) from reason  # type: ignore[arg-type]
urllib3.exceptions.MaxRetryError: HTTPSConnectionPool(host='api.wandb.ai', port=443): Max retries exceeded with url: /graphql (Caused by NameResolutionError("<urllib3.connection.HTTPSConnection object at 0x7f50f09ca490>: Failed to resolve 'api.wandb.ai' ([Errno -3] Temporary failure in name resolution)"))

During handling of the above exception, another exception occurred:

Traceback (most recent call last):
  File "/home/edo/.local/lib/python3.8/site-packages/wandb/sdk/lib/retry.py", line 131, in __call__
    result = self._call_fn(*args, **kwargs)
  File "/home/edo/.local/lib/python3.8/site-packages/wandb/sdk/internal/internal_api.py", line 285, in execute
    return self.client.execute(*args, **kwargs)  # type: ignore
  File "/home/edo/.local/lib/python3.8/site-packages/wandb/vendor/gql-0.2.0/wandb_gql/client.py", line 52, in execute
    result = self._get_result(document, *args, **kwargs)
  File "/home/edo/.local/lib/python3.8/site-packages/wandb/vendor/gql-0.2.0/wandb_gql/client.py", line 60, in _get_result
    return self.transport.execute(document, *args, **kwargs)
  File "/home/edo/.local/lib/python3.8/site-packages/wandb/sdk/lib/gql_request.py", line 55, in execute
    request = self.session.post(self.url, **post_args)
  File "/usr/lib/python3/dist-packages/requests/sessions.py", line 581, in post
    return self.request('POST', url, data=data, json=json, **kwargs)
  File "/usr/lib/python3/dist-packages/requests/sessions.py", line 533, in request
    resp = self.send(prep, **send_kwargs)
  File "/usr/lib/python3/dist-packages/requests/sessions.py", line 646, in send
    r = adapter.send(request, **kwargs)
  File "/usr/lib/python3/dist-packages/requests/adapters.py", line 516, in send
    raise ConnectionError(e, request=request)
requests.exceptions.ConnectionError: HTTPSConnectionPool(host='api.wandb.ai', port=443): Max retries exceeded with url: /graphql (Caused by NameResolutionError("<urllib3.connection.HTTPSConnection object at 0x7f50f09ca490>: Failed to resolve 'api.wandb.ai' ([Errno -3] Temporary failure in name resolution)"))
2023-06-13 08:25:50,999 DEBUG   HandlerThread:743961 [handler.py:handle_request():144] handle_request: keepalive
2023-06-13 08:25:52,458 DEBUG   HandlerThread:743961 [handler.py:handle_request():144] handle_request: shutdown
2023-06-13 08:25:52,458 INFO    HandlerThread:743961 [handler.py:finish():842] shutting down handler
2023-06-13 08:25:52,999 INFO    WriterThread:743961 [datastore.py:close():298] close: /home/edo/Desktop/orc/03_assignment/wandb/run-20230613_082545-n970g7bs/run-n970g7bs.wandb
2023-06-13 09:29:54,318 INFO    SenderThread:743961 [dir_watcher.py:__init__():219] watching files in: /home/edo/Desktop/orc/03_assignment/wandb/run-20230613_082545-n970g7bs/files
2023-06-13 09:29:54,319 INFO    SenderThread:743961 [sender.py:_start_run_threads():1124] run started: n970g7bs with start time 1686637545.964663
2023-06-13 09:29:54,319 INFO    SenderThread:743961 [sender.py:finish():1550] shutting down sender
2023-06-13 09:29:54,319 INFO    SenderThread:743961 [dir_watcher.py:finish():365] shutting down directory watcher
2023-06-13 09:29:55,319 INFO    SenderThread:743961 [dir_watcher.py:finish():395] scan: /home/edo/Desktop/orc/03_assignment/wandb/run-20230613_082545-n970g7bs/files
2023-06-13 09:29:55,319 INFO    SenderThread:743961 [dir_watcher.py:finish():409] scan save: /home/edo/Desktop/orc/03_assignment/wandb/run-20230613_082545-n970g7bs/files/config.yaml config.yaml
2023-06-13 09:29:55,319 INFO    SenderThread:743961 [file_pusher.py:finish():167] shutting down file pusher
2023-06-13 09:29:55,319 INFO    SenderThread:743961 [file_pusher.py:join():172] waiting for file pusher
2023-06-13 09:29:55,844 INFO    wandb-upload_0:743961 [upload_job.py:push():137] Uploaded file /home/edo/Desktop/orc/03_assignment/wandb/run-20230613_082545-n970g7bs/files/config.yaml
